2024-06-22 21:48:58,743 INFO    MainThread:7888 [wandb_setup.py:_flush():76] Current SDK version is 0.17.2
2024-06-22 21:48:58,743 INFO    MainThread:7888 [wandb_setup.py:_flush():76] Configure stats pid to 7888
2024-06-22 21:48:58,743 INFO    MainThread:7888 [wandb_setup.py:_flush():76] Loading settings from C:\Users\30533\.config\wandb\settings
2024-06-22 21:48:58,743 INFO    MainThread:7888 [wandb_setup.py:_flush():76] Loading settings from C:\Users\30533\Desktop\Pytorch-UNet-master\wandb\settings
2024-06-22 21:48:58,743 INFO    MainThread:7888 [wandb_setup.py:_flush():76] Loading settings from environment variables: {}
2024-06-22 21:48:58,743 INFO    MainThread:7888 [wandb_setup.py:_flush():76] Applying setup settings: {'_disable_service': False}
2024-06-22 21:48:58,744 INFO    MainThread:7888 [wandb_setup.py:_flush():76] Inferring run settings from compute environment: {'program_relpath': 'train.py', 'program_abspath': 'c:\\Users\\30533\\Desktop\\Pytorch-UNet-master\\train.py', 'program': 'c:/Users/30533/Desktop/Pytorch-UNet-master/train.py'}
2024-06-22 21:48:58,744 INFO    MainThread:7888 [wandb_setup.py:_flush():76] Applying login settings: {'anonymous': 'must'}
2024-06-22 21:48:58,744 INFO    MainThread:7888 [wandb_setup.py:_flush():76] Applying login settings: {'api_key': '***REDACTED***'}
2024-06-22 21:48:58,744 INFO    MainThread:7888 [wandb_init.py:_log_setup():520] Logging user logs to C:\Users\30533\Desktop\Pytorch-UNet-master\wandb\run-20240622_214858-zt245xgl\logs\debug.log
2024-06-22 21:48:58,744 INFO    MainThread:7888 [wandb_init.py:_log_setup():521] Logging internal logs to C:\Users\30533\Desktop\Pytorch-UNet-master\wandb\run-20240622_214858-zt245xgl\logs\debug-internal.log
2024-06-22 21:48:58,744 INFO    MainThread:7888 [wandb_init.py:init():560] calling init triggers
2024-06-22 21:48:58,744 INFO    MainThread:7888 [wandb_init.py:init():567] wandb.init called with sweep_config: {}
config: {}
2024-06-22 21:48:58,744 INFO    MainThread:7888 [wandb_init.py:init():610] starting backend
2024-06-22 21:48:58,744 INFO    MainThread:7888 [wandb_init.py:init():614] setting up manager
2024-06-22 21:48:58,746 INFO    MainThread:7888 [backend.py:_multiprocessing_setup():105] multiprocessing start_methods=spawn, using: spawn
2024-06-22 21:48:58,749 INFO    MainThread:7888 [wandb_init.py:init():622] backend started and connected
2024-06-22 21:48:58,754 INFO    MainThread:7888 [wandb_init.py:init():711] updated telemetry
2024-06-22 21:48:58,756 INFO    MainThread:7888 [wandb_init.py:init():744] communicating run to backend with 90.0 second timeout
2024-06-22 21:48:59,927 INFO    MainThread:7888 [wandb_run.py:_on_init():2402] communicating current version
2024-06-22 21:49:04,082 INFO    MainThread:7888 [wandb_run.py:_on_init():2411] got version response 
2024-06-22 21:49:04,082 INFO    MainThread:7888 [wandb_init.py:init():795] starting run threads in backend
2024-06-22 21:49:06,116 INFO    MainThread:7888 [wandb_run.py:_console_start():2380] atexit reg
2024-06-22 21:49:06,116 INFO    MainThread:7888 [wandb_run.py:_redirect():2235] redirect: wrap_raw
2024-06-22 21:49:06,116 INFO    MainThread:7888 [wandb_run.py:_redirect():2300] Wrapping output streams.
2024-06-22 21:49:06,116 INFO    MainThread:7888 [wandb_run.py:_redirect():2325] Redirects installed.
2024-06-22 21:49:06,119 INFO    MainThread:7888 [wandb_init.py:init():838] run started, returning control to user process
2024-06-22 21:49:06,119 INFO    MainThread:7888 [wandb_run.py:_config_callback():1382] config_cb None None {'epochs': 5, 'batch_size': 1, 'learning_rate': 1e-05, 'val_percent': 0.1, 'save_checkpoint': True, 'img_scale': 0.5, 'amp': False}
2024-06-22 22:08:47,566 INFO    MainThread:7888 [retry.py:__call__():172] Retry attempt failed:
urllib3.exceptions.SSLError: TLS/SSL connection has been closed (EOF) (_ssl.c:1135)

The above exception was the direct cause of the following exception:

urllib3.exceptions.ProxyError: ('Unable to connect to proxy', SSLError(SSLZeroReturnError(6, 'TLS/SSL connection has been closed (EOF) (_ssl.c:1135)')))

The above exception was the direct cause of the following exception:

Traceback (most recent call last):
  File "D:\Anaconda3\envs\U-net\lib\site-packages\requests\adapters.py", line 589, in send
    resp = conn.urlopen(
  File "D:\Anaconda3\envs\U-net\lib\site-packages\urllib3\connectionpool.py", line 843, in urlopen
    retries = retries.increment(
  File "D:\Anaconda3\envs\U-net\lib\site-packages\urllib3\util\retry.py", line 519, in increment
    raise MaxRetryError(_pool, url, reason) from reason  # type: ignore[arg-type]
urllib3.exceptions.MaxRetryError: HTTPSConnectionPool(host='api.wandb.ai', port=443): Max retries exceeded with url: /graphql (Caused by ProxyError('Unable to connect to proxy', SSLError(SSLZeroReturnError(6, 'TLS/SSL connection has been closed (EOF) (_ssl.c:1135)'))))

During handling of the above exception, another exception occurred:

Traceback (most recent call last):
  File "D:\Anaconda3\envs\U-net\lib\site-packages\wandb\sdk\lib\retry.py", line 131, in __call__
    result = self._call_fn(*args, **kwargs)
  File "D:\Anaconda3\envs\U-net\lib\site-packages\wandb\sdk\internal\internal_api.py", line 340, in execute
    return self.client.execute(*args, **kwargs)  # type: ignore
  File "D:\Anaconda3\envs\U-net\lib\site-packages\wandb\vendor\gql-0.2.0\wandb_gql\client.py", line 52, in execute
    result = self._get_result(document, *args, **kwargs)
  File "D:\Anaconda3\envs\U-net\lib\site-packages\wandb\vendor\gql-0.2.0\wandb_gql\client.py", line 60, in _get_result
    return self.transport.execute(document, *args, **kwargs)
  File "D:\Anaconda3\envs\U-net\lib\site-packages\wandb\sdk\lib\gql_request.py", line 58, in execute
    request = self.session.post(self.url, **post_args)
  File "D:\Anaconda3\envs\U-net\lib\site-packages\requests\sessions.py", line 637, in post
    return self.request("POST", url, data=data, json=json, **kwargs)
  File "D:\Anaconda3\envs\U-net\lib\site-packages\requests\sessions.py", line 589, in request
    resp = self.send(prep, **send_kwargs)
  File "D:\Anaconda3\envs\U-net\lib\site-packages\requests\sessions.py", line 703, in send
    r = adapter.send(request, **kwargs)
  File "D:\Anaconda3\envs\U-net\lib\site-packages\requests\adapters.py", line 616, in send
    raise ProxyError(e, request=request)
requests.exceptions.ProxyError: HTTPSConnectionPool(host='api.wandb.ai', port=443): Max retries exceeded with url: /graphql (Caused by ProxyError('Unable to connect to proxy', SSLError(SSLZeroReturnError(6, 'TLS/SSL connection has been closed (EOF) (_ssl.c:1135)'))))
